2019-04-10 16:38:50,268 ERROR: Exception on /reset_password_request [POST] [in c:\users\pc\appdata\local\programs\python\python37-32\lib\site-packages\flask\app.py:1761]
Traceback (most recent call last):
  File "c:\users\pc\appdata\local\programs\python\python37-32\lib\site-packages\flask\app.py", line 2292, in wsgi_app
    response = self.full_dispatch_request()
  File "c:\users\pc\appdata\local\programs\python\python37-32\lib\site-packages\flask\app.py", line 1815, in full_dispatch_request
    rv = self.handle_user_exception(e)
  File "c:\users\pc\appdata\local\programs\python\python37-32\lib\site-packages\flask\app.py", line 1718, in handle_user_exception
    reraise(exc_type, exc_value, tb)
  File "c:\users\pc\appdata\local\programs\python\python37-32\lib\site-packages\flask\_compat.py", line 35, in reraise
    raise value
  File "c:\users\pc\appdata\local\programs\python\python37-32\lib\site-packages\flask\app.py", line 1813, in full_dispatch_request
    rv = self.dispatch_request()
  File "c:\users\pc\appdata\local\programs\python\python37-32\lib\site-packages\flask\app.py", line 1799, in dispatch_request
    return self.view_functions[rule.endpoint](**req.view_args)
  File "C:\Users\PC\Documents\Git\Python\Microblog\app\routes.py", line 180, in reset_password_request
    send_password_reset_email(user)
  File "C:\Users\PC\Documents\Git\Python\Microblog\app\email.py", line 28, in send_password_reset_email
    user=user, token=token))
  File "C:\Users\PC\Documents\Git\Python\Microblog\app\email.py", line 16, in send_email
    mail.send(msg)
  File "c:\users\pc\appdata\local\programs\python\python37-32\lib\site-packages\flask_mail.py", line 492, in send
    message.send(connection)
  File "c:\users\pc\appdata\local\programs\python\python37-32\lib\site-packages\flask_mail.py", line 427, in send
    connection.send(self)
  File "c:\users\pc\appdata\local\programs\python\python37-32\lib\site-packages\flask_mail.py", line 192, in send
    message.rcpt_options)
  File "c:\users\pc\appdata\local\programs\python\python37-32\lib\smtplib.py", line 867, in sendmail
    raise SMTPSenderRefused(code, resp, from_addr)
smtplib.SMTPSenderRefused: (530, b'5.5.1 Authentication Required. Learn more at\n5.5.1  https://support.google.com/mail/?p=WantAuthError x3sm7037860lfn.64 - gsmtp', 'adelionek@gmail.com')
