2019-04-09 19:36:07,292 ERROR: Exception on /reset_password_request [POST] [in C:\Users\PC\Documents\Git\Python\Microblog\venv\lib\site-packages\flask\app.py:1761]
Traceback (most recent call last):
  File "C:\Users\PC\Documents\Git\Python\Microblog\venv\lib\site-packages\flask\app.py", line 2292, in wsgi_app
    response = self.full_dispatch_request()
  File "C:\Users\PC\Documents\Git\Python\Microblog\venv\lib\site-packages\flask\app.py", line 1815, in full_dispatch_request
    rv = self.handle_user_exception(e)
  File "C:\Users\PC\Documents\Git\Python\Microblog\venv\lib\site-packages\flask\app.py", line 1718, in handle_user_exception
    reraise(exc_type, exc_value, tb)
  File "C:\Users\PC\Documents\Git\Python\Microblog\venv\lib\site-packages\flask\_compat.py", line 35, in reraise
    raise value
  File "C:\Users\PC\Documents\Git\Python\Microblog\venv\lib\site-packages\flask\app.py", line 1813, in full_dispatch_request
    rv = self.dispatch_request()
  File "C:\Users\PC\Documents\Git\Python\Microblog\venv\lib\site-packages\flask\app.py", line 1799, in dispatch_request
    return self.view_functions[rule.endpoint](**req.view_args)
  File "C:\Users\PC\Documents\Git\Python\Microblog\app\routes.py", line 180, in reset_password_request
    send_password_reset_email(user)
  File "C:\Users\PC\Documents\Git\Python\Microblog\app\email.py", line 21, in send_password_reset_email
    user=user, token=token))
  File "C:\Users\PC\Documents\Git\Python\Microblog\app\email.py", line 10, in send_email
    mail.send(msg)
  File "C:\Users\PC\Documents\Git\Python\Microblog\venv\lib\site-packages\flask_mail.py", line 491, in send
    with self.connect() as connection:
  File "C:\Users\PC\Documents\Git\Python\Microblog\venv\lib\site-packages\flask_mail.py", line 144, in __enter__
    self.host = self.configure_host()
  File "C:\Users\PC\Documents\Git\Python\Microblog\venv\lib\site-packages\flask_mail.py", line 165, in configure_host
    host.login(self.mail.username, self.mail.password)
  File "C:\Users\PC\AppData\Local\Programs\Python\Python37-32\lib\smtplib.py", line 730, in login
    raise last_exception
  File "C:\Users\PC\AppData\Local\Programs\Python\Python37-32\lib\smtplib.py", line 721, in login
    initial_response_ok=initial_response_ok)
  File "C:\Users\PC\AppData\Local\Programs\Python\Python37-32\lib\smtplib.py", line 642, in auth
    raise SMTPAuthenticationError(code, resp)
smtplib.SMTPAuthenticationError: (535, b'5.7.8 Username and Password not accepted. Learn more at\n5.7.8  https://support.google.com/mail/?p=BadCredentials e1sm59928543wrw.66 - gsmtp')
